Workbook

Sheet in
A1: pais_de_origem | B1: razao_social | C1: cnpj | D1: logradouro | E1: cidade | F1: uf | G1: cep | H1: e_mail | I1: cotm | J1: adesao_ao_decreto_1563_95 | K1: vigencia_mês | L1: vigencia_dia | M1: vigencia_ano | N1: vigencia_data | O1: Coluna1
A2: BRASIL | B2: Agiliza Transportes E Logística Eireli | C2: 7953712000174 | D2: ROD. BR 277, KM 720, S/N, SALA 17 - ANEXO AO POSTO GASPARIN | F2: PR | G2: 85862000 | H2: leandro@agilizatransportes.com.br | I2: 0224-0107 | J2: Sim | K2: 11 | L2: 9 | M2: 2031 | N2: =DATE(M2,K2,L2) -> 48161 | O2: 00:00:00.000000
A3: BRASIL | B3: Alerta Transportes E Armazéns Gerais Ltda - Epp | C3: 10496449000146 | D3: Rodovia BR 277, km 720, nº 10.595 - Parque Três Fronteiras | F3: PR | G3: 85859688 | H3: delmar@transp-amizade.com.br | I3: 0900-0418 | J3: Sim | K3: 4 | L3: 5 | M3: 2028 | N3: =DATE(M3,K3,L3) -> 46848 | O3: 00:00:00.000000
A4: BRASIL | B4: Áquila Transporte De Cargas Ltda | C4: 3608196000190 | D4: STRC TRECHO 04 CONJ. C LOTE 09 - ZONA INDUSTRIAL | F4: DF | G4: 71225543 | H4: marcelo@aquilaexpress.com.br | I4: 0419-1110 | J4: Não | K4: 6 | L4: 29 | M4: 2032 | N4: =DATE(M4,K4,L4) -> 48394 | O4: 00:00:00.000000
A5: BRASIL | B5: Brazil Relocation & Services Ltda | C5: 4314143000129 | D5: RUA 13, QD. 49, LOTE 32 E 33 - PARQUE ESPLANADA II | F5: GO | G5: 72878036 | H5: adm1@brazilrelocatin.com | I5: 0412-0910 | J5: Sim | K5: 11 | L5: 12 | M5: 2030 | N5: =DATE(M5,K5,L5) -> 47799 | O5: 00:00:00.000000
A6: BRASIL | B6: Brucal Implementos Rodoviários Ltda | C6: 76188846000169 | D6: Rod. dos Minérios, km23,5, nº14552 - Areias | F6: PR | G6: 83514000 | H6: fernando@brucalimplementos.com.br | I6: 0659-1214 | J6: Sim | K6: 12 | L6: 30 | M6: 2024 | N6: =DATE(M6,K6,L6) -> 45656 | O6: 00:00:00.000000
A7: BRASIL | B7: Bun Log Serviços Logisticos Ltda | C7: 35957917000163 | D7: RUA ROQUE MEDALDO FRIAS, Nº 1341, GAÇPÃO 05, SALA 01, TÉRREO - RECREIO CAMPESTRE JOIA | F7: SP | G7: 13347035 | H7: rmendes@bentonit.com.br | I7: 1171-0621 | J7: Não | K7: 6 | L7: 22 | M7: 2031 | N7: =DATE(M7,K7,L7) -> 48021 | O7: 00:00:00.000000
A8: BRASIL | B8: Ciagram Portos E Navegação Da Amazônia Ltda | C8: 2900972000168 | D8: R I QUADRA E - LOTE 02 - SETOR INDUSTRIAL | F8: AM | G8: 69800000 | H8: logistica@masutti.com.br | I8: 1269-0622 | J8: Não | K8: 6 | L8: 22 | M8: 2032 | N8: =DATE(M8,K8,L8) -> 48387 | O8: 00:00:00.000000
A9: BRASIL | B9: Eckert & Ziegler Brasil Logistica Ltda | C9: 21423605000165 | D9: RUA MIGUEL NELSON BECHARA, 480 - TERREO - SALA 01 - BAIRRO - JARDIM PEREIRA LEITE | F9: SP | G9: 2712130 | H9: clarice.almeida@ezag.com | I9: 1085-0620 | J9: Sim | K9: 6 | L9: 12 | M9: 2030 | N9: =DATE(M9,K9,L9) -> 47646 | O9: 00:00:00.000000
A10: BRASIL | B10: Gencon Logistica Transportes E Armazéns Gerais Ltda | C10: 7263198000145 | D10: Av. Fernando Cerqueira César Coimbra - 830 - Bloco 02 - Parque Industrial Cacique - Londrina | F10: PR | G10: 86072110 | H10: italo@compager.com.br | I10: 0579-0913 | J10: Sim | K10: 9 | L10: 10 | M10: 2023 | N10: =DATE(M10,K10,L10) -> 45179 | O10: 00:00:00.000000
A11: PARAGUAI | B11: Grupo G3 Sociedade Anonima | C11: 53412 | D11: RUTA 6, CRUCE 14 DE MAYO, SANTA RITA | H11: maxypytterh@hotmail.com | I11: 0534-1212 | J11: Sim | K11: 12 | L11: 10 | M11: 2022 | N11: =DATE(M11,K11,L11) -> 44905 | O11: 00:00:00.000000
A12: BRASIL | B12: Jbs S.A. | C12: 2916265000160 | D12: AV. MARGINAL DIREITA DO TIETE, 500 - ANDAR 3 BLOCO I | F12: SP | G12: 5118100 | H12: cassio.sanches@jbs.com.br | I12: 1023-1019 | J12: Não | K12: 10 | L12: 1 | M12: 2029 | N12: =DATE(M12,K12,L12) -> 47392 | O12: 00:00:00.000000
A13: BRASIL | B13: Jr Pereira Transportes Ltda | C13: 51024961000177 | D13: EST DO CAIXA PARA, 120, LEVILÂNDIA, ANANINDEUA | F13: PA | G13: 67015520 | H13: didimopereira@hotmail.com | I13: 1407-0224 | J13: Não | K13: 2 | L13: 8 | M13: 2034 | N13: =DATE(M13,K13,L13) -> 48983 | O13: 00:00:00.000000
A14: BRASIL | B14: Katoen Natie Do Brasil Ltda | C14: 40924102000118 | D14: Avenida Viena, nº 419 - Distrito Industrial | F14: SP | G14: 13146055 | H14: regulatorios@katoennatie.com.br | I14: 0214-1106 | J14: Sim | K14: 10 | L14: 19 | M14: 2026 | N14: =DATE(M14,K14,L14) -> 46314 | O14: 00:00:00.000000
A15: BRASIL | B15: Leramarc Transportes E Logística Ltda | C15: 31000248000186 | D15: Rua Antonio Soster, 287 - Jardim Regina | F15: SP | G15: 13348897 | H15: rafael@leramarc.com.br | I15: 0987-0519 | J15: Não | K15: 5 | L15: 9 | M15: 2029 | N15: =DATE(M15,K15,L15) -> 47247 | O15: 00:00:00.000000
A16: BRASIL | B16: Logjato Transportes E Logistica Eireli | C16: 24514316000160 | D16: Segunda Avenida Bloco 1385A, Loja 1 | F16: DF | G16: 71710555 | H16: logjatobsb@gmail.com | I16: 0794-1016 | J16: Não | K16: 10 | L16: 5 | M16: 2026 | N16: =DATE(M16,K16,L16) -> 46300 | O16: 00:00:00.000000
A17: BRASIL | B17: Logmed Rio Armazenagem E Transporte Ltda | C17: 22044907000195 | D17: RUA FRANCISCO DE S E MELO, 01590, ARMAZEN Nº 103 GALPÃO 03 | F17: RJ | G17: 21010900 | H17: juridico@logmed.net | I17: 1028-1019 | J17: Não | K17: 10 | L17: 10 | M17: 2029 | N17: =DATE(M17,K17,L17) -> 47401 | O17: 00:00:00.000000
A18: DINAMARCA | B18: Maersk Line A/S | C18: 21386088000100 | D18: Esplanaden 50, 1098 | H18: gustavo.candido@maersk.com | I18: 0667-0315 | J18: Não | K18: 3 | L18: 25 | M18: 2025 | N18: =DATE(M18,K18,L18) -> 45741 | O18: 00:00:00.000000
A19: BRASIL | B19: Marca Sul Mudanças E Transportes Ltda | C19: 3126110000192 | D19: SCIA Quadra 08, conj.08, lote 13 | F19: DF | G19: 71250710 | H19: bsb@granero.com.br | I19: 0804-1116 | J19: Não | K19: 11 | L19: 11 | M19: 2026 | N19: =DATE(M19,K19,L19) -> 46337 | O19: 00:00:00.000000
A20: BRASIL | B20: Medylog Logística E Distribuição Ltda | C20: 11958200000178 | D20: RUA 24 (Polo de Modas) - LOTE 05 - QE 40 | F20: DF | G20: 71070524 | H20: MEDYLOGADM@GMAIL.COM | I20: 1311-1222 | J20: Não | K20: 12 | L20: 1 | M20: 2032 | N20: =DATE(M20,K20,L20) -> 48549 | O20: 00:00:00.000000
A21: BRASIL | B21: Megatranz Transportes Ltda | C21: 3061794000191 | D21: Av. Major Sylvio de Magalhães Padilha, 5200 - Bl. E - 5º andar - Conjunto 507 | F21: SP | G21: 5693000 | H21: MEGATRANZ@megatranz.com | I21: 0081-0605 | J21: Sim | K21: 6 | L21: 8 | M21: 2027 | N21: =DATE(M21,K21,L21) -> 46546 | O21: 00:00:00.000000
A22: BRASIL | B22: Mel Logística E Desembaraço Aduaneiro Eireli - Me | C22: 23756206000141 | D22: RUA WALTER MACHADO, 841 QUADRA D LOTE 05 ( CX POSTAL 187) | F22: GO | G22: 75375000 | H22: ricardo@mellogistica.com.br | I22: 0824-0217 | J22: Não | K22: 2 | L22: 10 | M22: 2027 | N22: =DATE(M22,K22,L22) -> 46428 | O22: 00:00:00.000000
A23: BRASIL | B23: Noble Brasil S.A | C23: 6315338000119 | D23: Avenida Rebouças nº 3.970, 22º andar - Condomínio Eldorado Business Tower | F23: SP | G23: 5402920 | H23: julianamedeiros@thisisnoble.com | I23: 0493-0512 | J23: Não | K23: 5 | L23: 25 | M23: 2022 | N23: =DATE(M23,K23,L23) -> 44706 | O23: 00:00:00.000000
A24: BRASIL | B24: Northin Logística E Servicos De Navegação Ltda | C24: 41248280000139 | D24: EST. ESTADUAL DO ANEL VIARIO S/N - GALPÃO 02 - SALA 02 - AREA RURAL | F24: RO | G24: 76914899 | H24: igorchaves98@hotmail.com | I24: 1394-1223 | J24: Não | K24: 12 | L24: 20 | M24: 2033 | N24: =DATE(M24,K24,L24) -> 48933 | O24: 00:00:00.000000
A25: BRASIL | B25: Nova Solução Logística & Transporte Ltda | C25: 33805990000194 | D25: Estrada Angela Trevisan Ciciliato, Nº 200, Galpão 01, Modulo 01 - Jardim Oliveira Camargo | F25: SP | G25: 13340730 | H25: diretoria@novasolucaolog.com | I25: 1440-0824 | J25: Não | K25: 8 | L25: 23 | M25: 2034 | N25: =DATE(M25,K25,L25) -> 49179 | O25: 00:00:00.000000
A26: BRASIL | B26: Pacheco Logística Ltda | C26: 14144376000184 | D26: RUA DONA MARGARIDA, Nº 903 | F26: RS | G26: 90240611 | H26: contabilidade@grupodarcypacheco.com.br | I26: 0568-0713 | J26: Sim | K26: 7 | L26: 22 | M26: 2023 | N26: =DATE(M26,K26,L26) -> 45129 | O26: 00:00:00.000000
A27: BRASIL | B27: Paradiso Giovanella Transportes Ltda | C27: 68979111000125 | D27: Rua José Simeão Rodrigues Agostinho, n º 502 - sala 03 - Bairro Água Espraiadas | F27: SP | G27: 6833300 | H27: adm@transgiovanella.com.br | I27: 0072-0505 | J27: Sim | K27: 6 | L27: 7 | M27: 2015 | N27: =DATE(M27,K27,L27) -> 42162 | O27: 00:00:00.000000
A28: BRASIL | B28: Rm Melo Transforporte Rodoviario E Aereo De Cargas Ltda | C28: 12323649000122 | D28: QUADRA 3, CONJUNTO B, LOTE 6, SETOR DE INDUSTRIAS BERNARDO SAYAO | F28: DF | G28: 71736302 | H28: RODRIGO@ALFAEXPRESSDF.COM.BR | I28: 1446-0924 | J28: Não | K28: 9 | L28: 30 | M28: 2034 | N28: =DATE(M28,K28,L28) -> 49217 | O28: 00:00:00.000000
A29: BRASIL | B29: Rodorei Transportes Ltda | C29: 68577659000149 | D29: Rua Salete nº 200 Cj. 81/82 | F29: SP | G29: 2016001 | H29: reinaldo@rodorei.com.br | I29: 0535-0113 | J29: Não | K29: 1 | L29: 3 | M29: 2023 | N29: =DATE(M29,K29,L29) -> 44929 | O29: 00:00:00.000000
A30: BRASIL | B30: Sec Figueiredo Ltda - Epp | C30: 43448117000145 | D30: RUA ESTELA Nº 515 - BLOCO H - 3 ANDAR - CJ 31 | F30: SP | G30: 4011002 | H30: eduardo@secfigueiredo.com.br | I30: 0524-1012 | J30: Não | K30: 10 | L30: 8 | M30: 2022 | N30: =DATE(M30,K30,L30) -> 44842 | O30: 00:00:00.000000
... A43: BRASIL | B43: Yes Brazil Express Cargas Ltda | C43: 2006743000102 | D43: RUA JOSE FERNANDES TEIXEIRA (ZUZA), 1091 - VILA ROSA | F43: SP | G43: 6317270 | H43: contab.luz@terra.com.br | I43: 1037-1119 | J43: Não | K43: 11 | L43: 12 | M43: 2029 | N43: =DATE(M43,K43,L43) -> 47434 | O43: 00:00:00.000000
A44: ALEMANHA | B44: HAPAG-LLOYD AG | C44: 8219447000168 | D44: Ballindamm, 25 - 20095 Hamburg - Germany | H44: intimacoes@hlag.com | I44: 0696-0715 | J44: Não | K44: 6 | L44: 23 | M44: 2035 | N44: =DATE(M44,K44,L44) -> 49483 | O44: 18:27:11.901169
A45: BRASIL | B45: Greca Transportes De Cargas S.A. | C45: 242640000108 | D45: Avenida das Araucarias nº 5126 - Chapada | F45: PR | G45: 83707000 | H45: andrea@grecaasfaltos.com.br | I45: 0510-0812 | J45: Sim | K45: 6 | L45: 22 | M45: 2032 | N45: =DATE(M45,K45,L45) -> 48387 | O45: 00:00:00.000000
A46: CHILE | B46: CSAV AUSTRAL SPA | C46: 71015 | D46: 14 Norte 976, Piso 12, Viña del Mar | H46: intimacoes@hlag.com | I46: 0710-0915 | J46: Não | K46: 7 | L46: 30 | M46: 2035 | N46: =DATE(M46,K46,L46) -> 49520 | O46: 18:41:05.863034
A47: CHILE | B47: CSAV AUSTRAL SPA | C47: 71015 | D47: 14 Norte 976, Piso 12, Viña del Mar | H47: luanabrancacio@hotmail.com | I47: 0710-0915 | J47: Não | K47: 7 | L47: 30 | M47: 2035 | N47: =DATE(M47,K47,L47) -> 49520 | O47: 18:41:05.863034
A48: BRASIL | B48: Tangara Logistica E Transportes Eireli - Epp | C48: 12900343000191 | D48: AV. ADINEI EMIDIO DE ALMEIDA, Nº 1893 - BAIRRO INDUSTRIAL | E48: Cacoal | F48: RO | G48: 76960970 | H48: fernando@piarara.com.br | I48: 1221-0122 | J48: Não | K48: 1 | L48: 25 | M48: 2032 | N48: =DATE(M48,K48,L48) -> 48238 | O48: 00:00:00.000000
A49: BRASIL | B49: Piarara Transportes Ltda | C49: 1746769000116 | D49: Rod. BR 364, KM 232, Lote 08-B, Gleba 08, Pavilhão A | E49: Cacoal | F49: RO | G49: 76960970 | H49: contabilidadetransportes@piarara.com.br | I49: 0348-1009 | J49: Sim | K49: 7 | L49: 11 | M49: 2029 | N49: =DATE(M49,K49,L49) -> 47310 | O49: 00:00:00.000000
A50: BRASIL | B50: P & F Transportes Eireli | C50: 13564310000180 | D50: EST DO BELMONT Nº 9349 KM 04 - BAIRRO NACIONAL | E50: Porto Velho | F50: RO | G50: 76801870 | H50: gustavoskiadv@gmail.com | I50: 0441-0711 | J50: Não | K50: 10 | L50: 4 | M50: 2031 | N50: =DATE(M50,K50,L50) -> 48125 | O50: 00:00:00.000000
A51: BRASIL | B51: Noroeste Transporte E Serviços Ltda | C51: 84552827000106 | D51: Rua João Pedro da Rocha, 2740 | E51: Porto Velho | F51: RO | G51: 76820888 | H51: dionemrios@uol.com.br | I51: 0462-1111 | J51: Não | K51: 11 | L51: 8 | M51: 2021 | N51: =DATE(M51,K51,L51) -> 44508 | O51: 00:00:00.000000
A52: BRASIL | B52: Bdx Logística Ltda | C52: 17589247000198 | D52: ESTRADA DO TERMINAL Nº 400 BAIRRO: PANAIR | E52: Porto Velho | F52: RO | G52: 76801370 | H52: bdxlogistica@gmail.com | I52: 1371-0923 | J52: Sim | K52: 9 | L52: 1 | M52: 2033 | N52: =DATE(M52,K52,L52) -> 48823 | O52: 00:00:00.000000
...

Sheet Gráficos
A1: uf | B1: Quantidade Empresas Habilitadas Multimodal | D1: pais_de_origem | E1: Quantidade de Empresas
A2: PR | B2: =COUNTIF(in!F:F,Gráficos!A2) -> 74
A3: DF | B3: =COUNTIF(in!F:F,Gráficos!A3) -> 64 | D3: PARAGUAI | E3: =COUNTIF(in!A:A,Gráficos!D3) -> 1
A4: GO | B4: =COUNTIF(in!F:F,Gráficos!A4) -> 25 | D4: DINAMARCA | E4: =COUNTIF(in!A:A,Gráficos!D4) -> 2
A5: SP | B5: =COUNTIF(in!F:F,Gráficos!A5) -> 569 | D5: ALEMANHA | E5: =COUNTIF(in!A:A,Gráficos!D5) -> 1
A6: AM | B6: =COUNTIF(in!F:F,Gráficos!A6) -> 98 | D6: CHILE | E6: =COUNTIF(in!A:A,Gráficos!D6) -> 2
B7: =COUNTIF(in!F:F,Gráficos!A7) -> 0 | D7: SUÍÇA | E7: =COUNTIF(in!A:A,Gráficos!D7) -> 1
A8: PA | B8: =COUNTIF(in!F:F,Gráficos!A8) -> 62
A9: RJ | B9: =COUNTIF(in!F:F,Gráficos!A9) -> 110
A10: RO | B10: =COUNTIF(in!F:F,Gráficos!A10) -> 7 | D10: Quantas empresas tem origem em outro país exceto o Brasil?
A11: RS | B11: =COUNTIF(in!F:F,Gráficos!A11) -> 82
A12: SC | B12: =COUNTIF(in!F:F,Gráficos!A12) -> 74
A13: MT | B13: =COUNTIF(in!F:F,Gráficos!A13) -> 12
A14: AC | B14: =COUNTIF(in!F:F,Gráficos!A14) -> 2
A15: RR | B15: =COUNTIF(in!F:F,Gráficos!A15) -> 1
A16: AP | B16: =COUNTIF(in!F:F,Gráficos!A16) -> 1
A17: TO | B17: =COUNTIF(in!F:F,Gráficos!A17) -> 2
A18: MA | B18: =COUNTIF(in!F:F,Gráficos!A18) -> 8
A19: PI | B19: =COUNTIF(in!F:F,Gráficos!A19) -> 2
A20: CE | B20: =COUNTIF(in!F:F,Gráficos!A20) -> 29
A21: RN | B21: =COUNTIF(in!F:F,Gráficos!A21) -> 6
A22: PB | B22: =COUNTIF(in!F:F,Gráficos!A22) -> 2
... A28: MS | B28: =COUNTIF(in!F:F,Gráficos!A28) -> 2
B29: =COUNTIF(in!F:F,Gráficos!A29) -> 0
A31: Qual estado tem mais empresas habilitadas multimodal?
